{
 "cells": [
  {
   "cell_type": "code",
   "execution_count": 79,
   "id": "tamil-factor",
   "metadata": {},
   "outputs": [
    {
     "name": "stderr",
     "output_type": "stream",
     "text": [
      "<ipython-input-79-830c3a369e7a>:5: FutureWarning: The pandas.datetime class is deprecated and will be removed from pandas in a future version. Import from datetime module instead.\n",
      "  from pandas import datetime\n"
     ]
    }
   ],
   "source": [
    "import numpy as np \n",
    "import pandas as pd \n",
    "import matplotlib.pyplot as plt\n",
    "from pandas.plotting import lag_plot\n",
    "from pandas import datetime\n",
    "from statsmodels.tsa.arima_model import ARIMA\n",
    "from sklearn.metrics import mean_squared_error"
   ]
  },
  {
   "cell_type": "code",
   "execution_count": 80,
   "id": "green-offense",
   "metadata": {},
   "outputs": [
    {
     "data": {
      "text/plain": [
       "date\n",
       "2010-05-05    93\n",
       "2011-12-05    89\n",
       "2011-05-05    87\n",
       "2012-12-05    79\n",
       "2012-05-05    94\n",
       "Name: RK, dtype: int64"
      ]
     },
     "execution_count": 80,
     "metadata": {},
     "output_type": "execute_result"
    }
   ],
   "source": [
    "df = pd.read_csv(\"data.csv\", header=0, parse_dates=[0], index_col=0, squeeze=True)\n",
    "df.head(5)"
   ]
  },
  {
   "cell_type": "code",
   "execution_count": 81,
   "id": "regular-reproduction",
   "metadata": {},
   "outputs": [
    {
     "ename": "KeyError",
     "evalue": "'RK'",
     "output_type": "error",
     "traceback": [
      "\u001b[0;31m---------------------------------------------------------------------------\u001b[0m",
      "\u001b[0;31mValueError\u001b[0m                                Traceback (most recent call last)",
      "\u001b[0;32mpandas/_libs/tslibs/conversion.pyx\u001b[0m in \u001b[0;36mpandas._libs.tslibs.conversion._convert_str_to_tsobject\u001b[0;34m()\u001b[0m\n",
      "\u001b[0;32mpandas/_libs/tslibs/parsing.pyx\u001b[0m in \u001b[0;36mpandas._libs.tslibs.parsing.parse_datetime_string\u001b[0;34m()\u001b[0m\n",
      "\u001b[0;32m~/.local/lib/python3.8/site-packages/dateutil/parser/_parser.py\u001b[0m in \u001b[0;36mparse\u001b[0;34m(timestr, parserinfo, **kwargs)\u001b[0m\n\u001b[1;32m   1357\u001b[0m     \u001b[0;32melse\u001b[0m\u001b[0;34m:\u001b[0m\u001b[0;34m\u001b[0m\u001b[0;34m\u001b[0m\u001b[0m\n\u001b[0;32m-> 1358\u001b[0;31m         \u001b[0;32mreturn\u001b[0m \u001b[0mDEFAULTPARSER\u001b[0m\u001b[0;34m.\u001b[0m\u001b[0mparse\u001b[0m\u001b[0;34m(\u001b[0m\u001b[0mtimestr\u001b[0m\u001b[0;34m,\u001b[0m \u001b[0;34m**\u001b[0m\u001b[0mkwargs\u001b[0m\u001b[0;34m)\u001b[0m\u001b[0;34m\u001b[0m\u001b[0;34m\u001b[0m\u001b[0m\n\u001b[0m\u001b[1;32m   1359\u001b[0m \u001b[0;34m\u001b[0m\u001b[0m\n",
      "\u001b[0;32m~/.local/lib/python3.8/site-packages/dateutil/parser/_parser.py\u001b[0m in \u001b[0;36mparse\u001b[0;34m(self, timestr, default, ignoretz, tzinfos, **kwargs)\u001b[0m\n\u001b[1;32m    648\u001b[0m         \u001b[0;32mif\u001b[0m \u001b[0mres\u001b[0m \u001b[0;32mis\u001b[0m \u001b[0;32mNone\u001b[0m\u001b[0;34m:\u001b[0m\u001b[0;34m\u001b[0m\u001b[0;34m\u001b[0m\u001b[0m\n\u001b[0;32m--> 649\u001b[0;31m             \u001b[0;32mraise\u001b[0m \u001b[0mValueError\u001b[0m\u001b[0;34m(\u001b[0m\u001b[0;34m\"Unknown string format:\"\u001b[0m\u001b[0;34m,\u001b[0m \u001b[0mtimestr\u001b[0m\u001b[0;34m)\u001b[0m\u001b[0;34m\u001b[0m\u001b[0;34m\u001b[0m\u001b[0m\n\u001b[0m\u001b[1;32m    650\u001b[0m \u001b[0;34m\u001b[0m\u001b[0m\n",
      "\u001b[0;31mValueError\u001b[0m: ('Unknown string format:', 'RK')",
      "\nDuring handling of the above exception, another exception occurred:\n",
      "\u001b[0;31mValueError\u001b[0m                                Traceback (most recent call last)",
      "\u001b[0;32m~/.local/lib/python3.8/site-packages/pandas/core/indexes/datetimes.py\u001b[0m in \u001b[0;36mget_loc\u001b[0;34m(self, key, method, tolerance)\u001b[0m\n\u001b[1;32m    663\u001b[0m             \u001b[0;32mtry\u001b[0m\u001b[0;34m:\u001b[0m\u001b[0;34m\u001b[0m\u001b[0;34m\u001b[0m\u001b[0m\n\u001b[0;32m--> 664\u001b[0;31m                 \u001b[0mkey\u001b[0m \u001b[0;34m=\u001b[0m \u001b[0mself\u001b[0m\u001b[0;34m.\u001b[0m\u001b[0m_maybe_cast_for_get_loc\u001b[0m\u001b[0;34m(\u001b[0m\u001b[0mkey\u001b[0m\u001b[0;34m)\u001b[0m\u001b[0;34m\u001b[0m\u001b[0;34m\u001b[0m\u001b[0m\n\u001b[0m\u001b[1;32m    665\u001b[0m             \u001b[0;32mexcept\u001b[0m \u001b[0mValueError\u001b[0m \u001b[0;32mas\u001b[0m \u001b[0merr\u001b[0m\u001b[0;34m:\u001b[0m\u001b[0;34m\u001b[0m\u001b[0;34m\u001b[0m\u001b[0m\n",
      "\u001b[0;32m~/.local/lib/python3.8/site-packages/pandas/core/indexes/datetimes.py\u001b[0m in \u001b[0;36m_maybe_cast_for_get_loc\u001b[0;34m(self, key)\u001b[0m\n\u001b[1;32m    691\u001b[0m         \u001b[0;31m# needed to localize naive datetimes or dates (GH 35690)\u001b[0m\u001b[0;34m\u001b[0m\u001b[0;34m\u001b[0m\u001b[0;34m\u001b[0m\u001b[0m\n\u001b[0;32m--> 692\u001b[0;31m         \u001b[0mkey\u001b[0m \u001b[0;34m=\u001b[0m \u001b[0mTimestamp\u001b[0m\u001b[0;34m(\u001b[0m\u001b[0mkey\u001b[0m\u001b[0;34m)\u001b[0m\u001b[0;34m\u001b[0m\u001b[0;34m\u001b[0m\u001b[0m\n\u001b[0m\u001b[1;32m    693\u001b[0m         \u001b[0;32mif\u001b[0m \u001b[0mkey\u001b[0m\u001b[0;34m.\u001b[0m\u001b[0mtzinfo\u001b[0m \u001b[0;32mis\u001b[0m \u001b[0;32mNone\u001b[0m\u001b[0;34m:\u001b[0m\u001b[0;34m\u001b[0m\u001b[0;34m\u001b[0m\u001b[0m\n",
      "\u001b[0;32mpandas/_libs/tslibs/timestamps.pyx\u001b[0m in \u001b[0;36mpandas._libs.tslibs.timestamps.Timestamp.__new__\u001b[0;34m()\u001b[0m\n",
      "\u001b[0;32mpandas/_libs/tslibs/conversion.pyx\u001b[0m in \u001b[0;36mpandas._libs.tslibs.conversion.convert_to_tsobject\u001b[0;34m()\u001b[0m\n",
      "\u001b[0;32mpandas/_libs/tslibs/conversion.pyx\u001b[0m in \u001b[0;36mpandas._libs.tslibs.conversion._convert_str_to_tsobject\u001b[0;34m()\u001b[0m\n",
      "\u001b[0;31mValueError\u001b[0m: could not convert string to Timestamp",
      "\nThe above exception was the direct cause of the following exception:\n",
      "\u001b[0;31mKeyError\u001b[0m                                  Traceback (most recent call last)",
      "\u001b[0;32m<ipython-input-81-f0670a32b819>\u001b[0m in \u001b[0;36m<module>\u001b[0;34m\u001b[0m\n\u001b[1;32m      1\u001b[0m \u001b[0mplt\u001b[0m\u001b[0;34m.\u001b[0m\u001b[0mfigure\u001b[0m\u001b[0;34m(\u001b[0m\u001b[0;34m)\u001b[0m\u001b[0;34m\u001b[0m\u001b[0;34m\u001b[0m\u001b[0m\n\u001b[0;32m----> 2\u001b[0;31m \u001b[0mlag_plot\u001b[0m\u001b[0;34m(\u001b[0m\u001b[0mdf\u001b[0m\u001b[0;34m[\u001b[0m\u001b[0;34m'RK'\u001b[0m\u001b[0;34m]\u001b[0m\u001b[0;34m,\u001b[0m \u001b[0mlag\u001b[0m\u001b[0;34m=\u001b[0m\u001b[0;36m3\u001b[0m\u001b[0;34m)\u001b[0m\u001b[0;34m\u001b[0m\u001b[0;34m\u001b[0m\u001b[0m\n\u001b[0m\u001b[1;32m      3\u001b[0m \u001b[0mplt\u001b[0m\u001b[0;34m.\u001b[0m\u001b[0mtitle\u001b[0m\u001b[0;34m(\u001b[0m\u001b[0;34m'TESLA Stock - Autocorrelation plot with lag = 3'\u001b[0m\u001b[0;34m)\u001b[0m\u001b[0;34m\u001b[0m\u001b[0;34m\u001b[0m\u001b[0m\n\u001b[1;32m      4\u001b[0m \u001b[0mplt\u001b[0m\u001b[0;34m.\u001b[0m\u001b[0mshow\u001b[0m\u001b[0;34m(\u001b[0m\u001b[0;34m)\u001b[0m\u001b[0;34m\u001b[0m\u001b[0;34m\u001b[0m\u001b[0m\n",
      "\u001b[0;32m~/.local/lib/python3.8/site-packages/pandas/core/series.py\u001b[0m in \u001b[0;36m__getitem__\u001b[0;34m(self, key)\u001b[0m\n\u001b[1;32m    851\u001b[0m \u001b[0;34m\u001b[0m\u001b[0m\n\u001b[1;32m    852\u001b[0m         \u001b[0;32melif\u001b[0m \u001b[0mkey_is_scalar\u001b[0m\u001b[0;34m:\u001b[0m\u001b[0;34m\u001b[0m\u001b[0;34m\u001b[0m\u001b[0m\n\u001b[0;32m--> 853\u001b[0;31m             \u001b[0;32mreturn\u001b[0m \u001b[0mself\u001b[0m\u001b[0;34m.\u001b[0m\u001b[0m_get_value\u001b[0m\u001b[0;34m(\u001b[0m\u001b[0mkey\u001b[0m\u001b[0;34m)\u001b[0m\u001b[0;34m\u001b[0m\u001b[0;34m\u001b[0m\u001b[0m\n\u001b[0m\u001b[1;32m    854\u001b[0m \u001b[0;34m\u001b[0m\u001b[0m\n\u001b[1;32m    855\u001b[0m         \u001b[0;32mif\u001b[0m \u001b[0mis_hashable\u001b[0m\u001b[0;34m(\u001b[0m\u001b[0mkey\u001b[0m\u001b[0;34m)\u001b[0m\u001b[0;34m:\u001b[0m\u001b[0;34m\u001b[0m\u001b[0;34m\u001b[0m\u001b[0m\n",
      "\u001b[0;32m~/.local/lib/python3.8/site-packages/pandas/core/series.py\u001b[0m in \u001b[0;36m_get_value\u001b[0;34m(self, label, takeable)\u001b[0m\n\u001b[1;32m    959\u001b[0m \u001b[0;34m\u001b[0m\u001b[0m\n\u001b[1;32m    960\u001b[0m         \u001b[0;31m# Similar to Index.get_value, but we do not fall back to positional\u001b[0m\u001b[0;34m\u001b[0m\u001b[0;34m\u001b[0m\u001b[0;34m\u001b[0m\u001b[0m\n\u001b[0;32m--> 961\u001b[0;31m         \u001b[0mloc\u001b[0m \u001b[0;34m=\u001b[0m \u001b[0mself\u001b[0m\u001b[0;34m.\u001b[0m\u001b[0mindex\u001b[0m\u001b[0;34m.\u001b[0m\u001b[0mget_loc\u001b[0m\u001b[0;34m(\u001b[0m\u001b[0mlabel\u001b[0m\u001b[0;34m)\u001b[0m\u001b[0;34m\u001b[0m\u001b[0;34m\u001b[0m\u001b[0m\n\u001b[0m\u001b[1;32m    962\u001b[0m         \u001b[0;32mreturn\u001b[0m \u001b[0mself\u001b[0m\u001b[0;34m.\u001b[0m\u001b[0mindex\u001b[0m\u001b[0;34m.\u001b[0m\u001b[0m_get_values_for_loc\u001b[0m\u001b[0;34m(\u001b[0m\u001b[0mself\u001b[0m\u001b[0;34m,\u001b[0m \u001b[0mloc\u001b[0m\u001b[0;34m,\u001b[0m \u001b[0mlabel\u001b[0m\u001b[0;34m)\u001b[0m\u001b[0;34m\u001b[0m\u001b[0;34m\u001b[0m\u001b[0m\n\u001b[1;32m    963\u001b[0m \u001b[0;34m\u001b[0m\u001b[0m\n",
      "\u001b[0;32m~/.local/lib/python3.8/site-packages/pandas/core/indexes/datetimes.py\u001b[0m in \u001b[0;36mget_loc\u001b[0;34m(self, key, method, tolerance)\u001b[0m\n\u001b[1;32m    664\u001b[0m                 \u001b[0mkey\u001b[0m \u001b[0;34m=\u001b[0m \u001b[0mself\u001b[0m\u001b[0;34m.\u001b[0m\u001b[0m_maybe_cast_for_get_loc\u001b[0m\u001b[0;34m(\u001b[0m\u001b[0mkey\u001b[0m\u001b[0;34m)\u001b[0m\u001b[0;34m\u001b[0m\u001b[0;34m\u001b[0m\u001b[0m\n\u001b[1;32m    665\u001b[0m             \u001b[0;32mexcept\u001b[0m \u001b[0mValueError\u001b[0m \u001b[0;32mas\u001b[0m \u001b[0merr\u001b[0m\u001b[0;34m:\u001b[0m\u001b[0;34m\u001b[0m\u001b[0;34m\u001b[0m\u001b[0m\n\u001b[0;32m--> 666\u001b[0;31m                 \u001b[0;32mraise\u001b[0m \u001b[0mKeyError\u001b[0m\u001b[0;34m(\u001b[0m\u001b[0mkey\u001b[0m\u001b[0;34m)\u001b[0m \u001b[0;32mfrom\u001b[0m \u001b[0merr\u001b[0m\u001b[0;34m\u001b[0m\u001b[0;34m\u001b[0m\u001b[0m\n\u001b[0m\u001b[1;32m    667\u001b[0m \u001b[0;34m\u001b[0m\u001b[0m\n\u001b[1;32m    668\u001b[0m         \u001b[0;32melif\u001b[0m \u001b[0misinstance\u001b[0m\u001b[0;34m(\u001b[0m\u001b[0mkey\u001b[0m\u001b[0;34m,\u001b[0m \u001b[0mtimedelta\u001b[0m\u001b[0;34m)\u001b[0m\u001b[0;34m:\u001b[0m\u001b[0;34m\u001b[0m\u001b[0;34m\u001b[0m\u001b[0m\n",
      "\u001b[0;31mKeyError\u001b[0m: 'RK'"
     ]
    },
    {
     "data": {
      "text/plain": [
       "<Figure size 432x288 with 0 Axes>"
      ]
     },
     "metadata": {},
     "output_type": "display_data"
    }
   ],
   "source": [
    "plt.figure()\n",
    "lag_plot(df['RK'], lag=3)\n",
    "plt.title('TESLA Stock - Autocorrelation plot with lag = 3')\n",
    "plt.show()"
   ]
  },
  {
   "cell_type": "code",
   "execution_count": null,
   "id": "computational-omega",
   "metadata": {},
   "outputs": [],
   "source": []
  }
 ],
 "metadata": {
  "kernelspec": {
   "display_name": "Python 3",
   "language": "python",
   "name": "python3"
  },
  "language_info": {
   "codemirror_mode": {
    "name": "ipython",
    "version": 3
   },
   "file_extension": ".py",
   "mimetype": "text/x-python",
   "name": "python",
   "nbconvert_exporter": "python",
   "pygments_lexer": "ipython3",
   "version": "3.8.5"
  }
 },
 "nbformat": 4,
 "nbformat_minor": 5
}
